<?xml version="1.0"?>
<robot xmlns:xacro="http://www.ros.org/wiki/xacro">
  <xacro:macro name="flexipod_joint_transmission" params="name">
    <transmission name="${name}_transmission">
      <type>transmission_interface/SimpleTransmission</type>
      <joint name="${name}_joint">
        <hardwareInterface>EffortJointInterface</hardwareInterface>
      </joint>
      <actuator name="${name}_motor">
        <mechanicalReduction>1</mechanicalReduction>
        <hardwareInterface>EffortJointInterface</hardwareInterface>
      </actuator>
    </transmission>
  </xacro:macro>

  <xacro:macro name="example_quadruped_leg" params="name parent *origin">
    <link name="${name}_coxa_link">
      <visual>
        <geometry><mesh filename="package://example_quadruped_description/meshes/coxa_link.stl" /></geometry>
        <origin rpy="${-pi / 2} 0 ${pi / 2}" />
        <material name="example_quadruped_material" />
      </visual>
      <collision>
        <geometry><mesh filename="package://example_quadruped_description/meshes/coxa_link.stl" /></geometry>
        <origin rpy="${-pi / 2} 0 ${pi / 2}" />
      </collision>
      <inertial>
        <origin xyz="0.0028255 0.016487 -0.038239" />
        <mass value="0.054025" />
        <inertia ixx="4.2638E-05" ixy="-1.8883E-07" ixz="-4.2377E-06" iyy="5.3271E-05" iyz="2.555E-06" izz="2.8624E-05" />
      </inertial>
    </link>

    <link name="${name}_femur_link">
      <visual>
        <geometry><mesh filename="package://example_quadruped_description/meshes/femur_link.stl" /></geometry>
        <origin rpy="0 0 ${-pi / 2}" />
        <material name="example_quadruped_material" />
      </visual>
      <collision>
        <geometry><mesh filename="package://example_quadruped_description/meshes/femur_link.stl" /></geometry>
        <origin rpy="0 0 ${-pi / 2}" />
      </collision>
      <inertial>
        <origin xyz="4.1633E-17 0.0545 -0.0002317" />
        <mass value="0.18426" />
        <inertia ixx="0.00033345" ixy="-6.5254E-08" ixz="-1.5302E-19" iyy="4.8055E-05" iyz="-2.3378E-19" izz="0.0003165" />
      </inertial>
    </link>

    <link name="${name}_tibia_link">
      <visual>
        <geometry><mesh filename="package://example_quadruped_description/meshes/tibia_link.stl" /></geometry>
        <origin rpy="${-pi / 2} ${-pi / 2} 0" />
        <material name="example_quadruped_material" />
      </visual>
      <collision>
        <geometry><mesh filename="package://example_quadruped_description/meshes/tibia_link.stl" /></geometry>
        <origin rpy="${-pi / 2} ${-pi / 2} 0" />
      </collision>
      <inertial>
        <origin xyz="-0.001867 0.094612 7.7874E-06" />
        <mass value="0.08176" />
        <inertia ixx="0.0009073" ixy="1.4442E-05" ixz="1.1866E-09" iyy="2.5535E-05" iyz="9.4278E-08" izz="0.00092384" />
      </inertial>
    </link>

    <link name="${name}_foot_link" />

    <joint name="${name}_coxa_joint" type="revolute">
      <parent link="${parent}" />
      <child link="${name}_coxa_link" />

      <xacro:insert_block name="origin" />
      <axis xyz="0 0 1" />

      <limit lower="-1.8326" upper="1.8326" effort="3.1" velocity="7" />
    </joint>

    <joint name="${name}_femur_joint" type="revolute">
      <parent link="${name}_coxa_link" />
      <child link="${name}_femur_link" />

      <origin xyz="0.066 0 0" rpy="${-pi / 2} 0 0" />
      <axis xyz="0 0 1" />

      <limit lower="-1.9199" upper="1.9199" effort="10" velocity="5.5" />
    </joint>

    <joint name="${name}_tibia_joint" type="revolute">
      <parent link="${name}_femur_link" />
      <child link="${name}_tibia_link" />

      <origin xyz="0.109 0 0" rpy="0 0 0" />
      <axis xyz="0 0 1" />

      <limit lower="-1.9199" upper="1.9199" effort="10" velocity="5.5" />
    </joint>

    <joint name="${name}_foot_joint" type="fixed">
      <parent link="${name}_tibia_link" />
      <child link="${name}_foot_link" />

      <origin xyz="0.324 0 0" rpy="0 ${pi / 2} 0" />
    </joint>

    <xacro:flexipod_joint_transmission name="${name}_coxa" />
    <xacro:flexipod_joint_transmission name="${name}_femur" />
    <xacro:flexipod_joint_transmission name="${name}_tibia" />
  </xacro:macro>
</robot>
