<?xml version="1.0"?>
<robot xmlns:xacro="http://www.ros.org/wiki/xacro">
  <xacro:macro name="flexipod_joint_transmission" params="name">
    <transmission name="${name}_transmission">
      <type>transmission_interface/SimpleTransmission</type>
      <joint name="${name}_joint">
        <hardwareInterface>EffortJointInterface</hardwareInterface>
      </joint>
      <actuator name="${name}_motor">
        <mechanicalReduction>1</mechanicalReduction>
        <hardwareInterface>EffortJointInterface</hardwareInterface>
      </actuator>
    </transmission>
  </xacro:macro>

  <xacro:macro name="example_quadruped_leg" params="name parent *origin">
    <link name="${name}_coxa_link">
      <visual>
        <geometry><mesh filename="package://example_quadruped_description/meshes/coxa_link.stl" /></geometry>
        <origin rpy="${-pi / 2} 0 ${pi / 2}" />
        <material name="example_quadruped_material" />
      </visual>
      <collision>
        <geometry><mesh filename="package://example_quadruped_description/meshes/coxa_link.stl" /></geometry>
        <origin rpy="${-pi / 2} 0 ${pi / 2}" />
      </collision>
    </link>

    <link name="${name}_femur_link">
      <visual>
        <geometry><mesh filename="package://example_quadruped_description/meshes/femur_link.stl" /></geometry>
        <origin rpy="0 0 ${-pi / 2}" />
        <material name="example_quadruped_material" />
      </visual>
      <collision>
        <geometry><mesh filename="package://example_quadruped_description/meshes/femur_link.stl" /></geometry>
        <origin rpy="0 0 ${-pi / 2}" />
      </collision>
    </link>

    <link name="${name}_tibia_link">
      <visual>
        <geometry><mesh filename="package://example_quadruped_description/meshes/tibia_link.stl" /></geometry>
        <origin rpy="${-pi / 2} ${-pi / 2} 0" />
        <material name="example_quadruped_material" />
      </visual>
      <collision>
        <geometry><mesh filename="package://example_quadruped_description/meshes/tibia_link.stl" /></geometry>
        <origin rpy="${-pi / 2} ${-pi / 2} 0" />
      </collision>
    </link>

    <link name="${name}_foot_link" />

    <joint name="${name}_coxa_joint" type="revolute">
      <parent link="${parent}" />
      <child link="${name}_coxa_link" />

      <xacro:insert_block name="origin" />
      <axis xyz="0 0 1" />

      <limit lower="-1.8326" upper="1.8326" effort="3.1" velocity="7" />
    </joint>

    <joint name="${name}_femur_joint" type="revolute">
      <parent link="${name}_coxa_link" />
      <child link="${name}_femur_link" />

      <origin xyz="0.066 0 0" rpy="${-pi / 2} 0 0" />
      <axis xyz="0 0 1" />

      <limit lower="-1.9199" upper="1.9199" effort="10" velocity="5.5" />
    </joint>

    <joint name="${name}_tibia_joint" type="revolute">
      <parent link="${name}_femur_link" />
      <child link="${name}_tibia_link" />

      <origin xyz="0.109 0 0" rpy="0 0 0" />
      <axis xyz="0 0 1" />

      <limit lower="-1.9199" upper="1.9199" effort="10" velocity="5.5" />
    </joint>

    <joint name="${name}_foot_joint" type="fixed">
      <parent link="${name}_tibia_link" />
      <child link="${name}_foot_link" />

      <origin xyz="0.324 0 0" rpy="0 ${pi / 2} 0" />
    </joint>

    <xacro:flexipod_joint_transmission name="${name}_coxa" />
    <xacro:flexipod_joint_transmission name="${name}_femur" />
    <xacro:flexipod_joint_transmission name="${name}_tibia" />
  </xacro:macro>
</robot>
